
Epoch: 1
Traceback (most recent call last):
  File "main.py", line 87, in <module>
    train_loss = train_func(model, loader_train, optimizer, scaler)
  File "/homes/n20darja/StageCesureCoeur/predict_tavi/Learning2D/train.py", line 29, in train_func
    for batch in loader_train:
  File "/opt/campux/virtualenv/deeplearning-u20-rtx-3080-pytorch-1.11/lib/python3.8/site-packages/torch/utils/data/dataloader.py", line 530, in __next__
    data = self._next_data()
  File "/opt/campux/virtualenv/deeplearning-u20-rtx-3080-pytorch-1.11/lib/python3.8/site-packages/torch/utils/data/dataloader.py", line 1224, in _next_data
    return self._process_data(data)
  File "/opt/campux/virtualenv/deeplearning-u20-rtx-3080-pytorch-1.11/lib/python3.8/site-packages/torch/utils/data/dataloader.py", line 1250, in _process_data
    data.reraise()
  File "/opt/campux/virtualenv/deeplearning-u20-rtx-3080-pytorch-1.11/lib/python3.8/site-packages/torch/_utils.py", line 457, in reraise
    raise exception
RuntimeError: Caught RuntimeError in DataLoader worker process 0.
Original Traceback (most recent call last):
  File "/homes/n20darja/.local/lib/python3.8/site-packages/albumentations/augmentations/functional.py", line 905, in to_float
    max_value = MAX_VALUES_BY_DTYPE[img.dtype]
KeyError: dtype('int16')
During handling of the above exception, another exception occurred:
Traceback (most recent call last):
  File "/opt/campux/virtualenv/deeplearning-u20-rtx-3080-pytorch-1.11/lib/python3.8/site-packages/torch/utils/data/_utils/worker.py", line 287, in _worker_loop
    data = fetcher.fetch(index)
  File "/opt/campux/virtualenv/deeplearning-u20-rtx-3080-pytorch-1.11/lib/python3.8/site-packages/torch/utils/data/_utils/fetch.py", line 49, in fetch
    data = [self.dataset[idx] for idx in possibly_batched_index]
  File "/opt/campux/virtualenv/deeplearning-u20-rtx-3080-pytorch-1.11/lib/python3.8/site-packages/torch/utils/data/_utils/fetch.py", line 49, in <listcomp>
    data = [self.dataset[idx] for idx in possibly_batched_index]
  File "/homes/n20darja/StageCesureCoeur/predict_tavi/Learning2D/Dataloader.py", line 56, in __getitem__
    image = self.transform(image=image)['image']
  File "/homes/n20darja/.local/lib/python3.8/site-packages/albumentations/core/composition.py", line 205, in __call__
    data = t(**data)
  File "/homes/n20darja/.local/lib/python3.8/site-packages/albumentations/core/transforms_interface.py", line 118, in __call__
    return self.apply_with_params(params, **kwargs)
  File "/homes/n20darja/.local/lib/python3.8/site-packages/albumentations/core/transforms_interface.py", line 131, in apply_with_params
    res[key] = target_function(arg, **dict(params, **target_dependencies))
  File "/homes/n20darja/.local/lib/python3.8/site-packages/albumentations/augmentations/transforms.py", line 1478, in apply
    return F.to_float(img, self.max_value)
  File "/homes/n20darja/.local/lib/python3.8/site-packages/albumentations/augmentations/functional.py", line 907, in to_float
    raise RuntimeError(
RuntimeError: Can't infer the maximum value for dtype int16. You need to specify the maximum value manually by passing the max_value argument
Traceback (most recent call last):
  File "main.py", line 87, in <module>
    train_loss = train_func(model, loader_train, optimizer, scaler)
  File "/homes/n20darja/StageCesureCoeur/predict_tavi/Learning2D/train.py", line 29, in train_func
    for batch in loader_train:
  File "/opt/campux/virtualenv/deeplearning-u20-rtx-3080-pytorch-1.11/lib/python3.8/site-packages/torch/utils/data/dataloader.py", line 530, in __next__
    data = self._next_data()
  File "/opt/campux/virtualenv/deeplearning-u20-rtx-3080-pytorch-1.11/lib/python3.8/site-packages/torch/utils/data/dataloader.py", line 1224, in _next_data
    return self._process_data(data)
  File "/opt/campux/virtualenv/deeplearning-u20-rtx-3080-pytorch-1.11/lib/python3.8/site-packages/torch/utils/data/dataloader.py", line 1250, in _process_data
    data.reraise()
  File "/opt/campux/virtualenv/deeplearning-u20-rtx-3080-pytorch-1.11/lib/python3.8/site-packages/torch/_utils.py", line 457, in reraise
    raise exception
RuntimeError: Caught RuntimeError in DataLoader worker process 0.
Original Traceback (most recent call last):
  File "/homes/n20darja/.local/lib/python3.8/site-packages/albumentations/augmentations/functional.py", line 905, in to_float
    max_value = MAX_VALUES_BY_DTYPE[img.dtype]
KeyError: dtype('int16')
During handling of the above exception, another exception occurred:
Traceback (most recent call last):
  File "/opt/campux/virtualenv/deeplearning-u20-rtx-3080-pytorch-1.11/lib/python3.8/site-packages/torch/utils/data/_utils/worker.py", line 287, in _worker_loop
    data = fetcher.fetch(index)
  File "/opt/campux/virtualenv/deeplearning-u20-rtx-3080-pytorch-1.11/lib/python3.8/site-packages/torch/utils/data/_utils/fetch.py", line 49, in fetch
    data = [self.dataset[idx] for idx in possibly_batched_index]
  File "/opt/campux/virtualenv/deeplearning-u20-rtx-3080-pytorch-1.11/lib/python3.8/site-packages/torch/utils/data/_utils/fetch.py", line 49, in <listcomp>
    data = [self.dataset[idx] for idx in possibly_batched_index]
  File "/homes/n20darja/StageCesureCoeur/predict_tavi/Learning2D/Dataloader.py", line 56, in __getitem__
    image = self.transform(image=image)['image']
  File "/homes/n20darja/.local/lib/python3.8/site-packages/albumentations/core/composition.py", line 205, in __call__
    data = t(**data)
  File "/homes/n20darja/.local/lib/python3.8/site-packages/albumentations/core/transforms_interface.py", line 118, in __call__
    return self.apply_with_params(params, **kwargs)
  File "/homes/n20darja/.local/lib/python3.8/site-packages/albumentations/core/transforms_interface.py", line 131, in apply_with_params
    res[key] = target_function(arg, **dict(params, **target_dependencies))
  File "/homes/n20darja/.local/lib/python3.8/site-packages/albumentations/augmentations/transforms.py", line 1478, in apply
    return F.to_float(img, self.max_value)
  File "/homes/n20darja/.local/lib/python3.8/site-packages/albumentations/augmentations/functional.py", line 907, in to_float
    raise RuntimeError(
RuntimeError: Can't infer the maximum value for dtype int16. You need to specify the maximum value manually by passing the max_value argument