
Epoch 1
Traceback (most recent call last):
  File "main.py", line 80, in <module>
    ssl_train_losses, model, last_checkpoint = train_scl(model, projector, train_loader, train_transform, criterion, optimizer, scheduler, dict_config['n_epoch_proj'], use_wandb)
  File "/homes/n20darja/StageCesureCoeur/predict_tavi/ContrastiveLearning/scl.py", line 44, in train_scl
    train_loss = train_epoch_scl(encoder, projector, train_loader, train_transform, criterion, optimizer, scheduler)
  File "/homes/n20darja/StageCesureCoeur/predict_tavi/ContrastiveLearning/scl.py", line 10, in train_epoch_scl
    for data, target, _ in train_loader:
  File "/opt/campux/virtualenv/deeplearning-u20-rtx-3080-pytorch-1.11/lib/python3.8/site-packages/torch/utils/data/dataloader.py", line 530, in __next__
    data = self._next_data()
  File "/opt/campux/virtualenv/deeplearning-u20-rtx-3080-pytorch-1.11/lib/python3.8/site-packages/torch/utils/data/dataloader.py", line 1224, in _next_data
    return self._process_data(data)
  File "/opt/campux/virtualenv/deeplearning-u20-rtx-3080-pytorch-1.11/lib/python3.8/site-packages/torch/utils/data/dataloader.py", line 1250, in _process_data
    data.reraise()
  File "/opt/campux/virtualenv/deeplearning-u20-rtx-3080-pytorch-1.11/lib/python3.8/site-packages/torch/_utils.py", line 457, in reraise
    raise exception
NameError: Caught NameError in DataLoader worker process 0.
Original Traceback (most recent call last):
  File "/opt/campux/virtualenv/deeplearning-u20-rtx-3080-pytorch-1.11/lib/python3.8/site-packages/torch/utils/data/_utils/worker.py", line 287, in _worker_loop
    data = fetcher.fetch(index)
  File "/opt/campux/virtualenv/deeplearning-u20-rtx-3080-pytorch-1.11/lib/python3.8/site-packages/torch/utils/data/_utils/fetch.py", line 49, in fetch
    data = [self.dataset[idx] for idx in possibly_batched_index]
  File "/opt/campux/virtualenv/deeplearning-u20-rtx-3080-pytorch-1.11/lib/python3.8/site-packages/torch/utils/data/_utils/fetch.py", line 49, in <listcomp>
    data = [self.dataset[idx] for idx in possibly_batched_index]
  File "/homes/n20darja/StageCesureCoeur/predict_tavi/ContrastiveLearning/Dataloader.py", line 25, in __getitem__
    hsm_cluster = pd.read_csv('clusters_hauteur.csv')
NameError: name 'pd' is not defined
Traceback (most recent call last):
  File "main.py", line 80, in <module>
    ssl_train_losses, model, last_checkpoint = train_scl(model, projector, train_loader, train_transform, criterion, optimizer, scheduler, dict_config['n_epoch_proj'], use_wandb)
  File "/homes/n20darja/StageCesureCoeur/predict_tavi/ContrastiveLearning/scl.py", line 44, in train_scl
    train_loss = train_epoch_scl(encoder, projector, train_loader, train_transform, criterion, optimizer, scheduler)
  File "/homes/n20darja/StageCesureCoeur/predict_tavi/ContrastiveLearning/scl.py", line 10, in train_epoch_scl
    for data, target, _ in train_loader:
  File "/opt/campux/virtualenv/deeplearning-u20-rtx-3080-pytorch-1.11/lib/python3.8/site-packages/torch/utils/data/dataloader.py", line 530, in __next__
    data = self._next_data()
  File "/opt/campux/virtualenv/deeplearning-u20-rtx-3080-pytorch-1.11/lib/python3.8/site-packages/torch/utils/data/dataloader.py", line 1224, in _next_data
    return self._process_data(data)
  File "/opt/campux/virtualenv/deeplearning-u20-rtx-3080-pytorch-1.11/lib/python3.8/site-packages/torch/utils/data/dataloader.py", line 1250, in _process_data
    data.reraise()
  File "/opt/campux/virtualenv/deeplearning-u20-rtx-3080-pytorch-1.11/lib/python3.8/site-packages/torch/_utils.py", line 457, in reraise
    raise exception
NameError: Caught NameError in DataLoader worker process 0.
Original Traceback (most recent call last):
  File "/opt/campux/virtualenv/deeplearning-u20-rtx-3080-pytorch-1.11/lib/python3.8/site-packages/torch/utils/data/_utils/worker.py", line 287, in _worker_loop
    data = fetcher.fetch(index)
  File "/opt/campux/virtualenv/deeplearning-u20-rtx-3080-pytorch-1.11/lib/python3.8/site-packages/torch/utils/data/_utils/fetch.py", line 49, in fetch
    data = [self.dataset[idx] for idx in possibly_batched_index]
  File "/opt/campux/virtualenv/deeplearning-u20-rtx-3080-pytorch-1.11/lib/python3.8/site-packages/torch/utils/data/_utils/fetch.py", line 49, in <listcomp>
    data = [self.dataset[idx] for idx in possibly_batched_index]
  File "/homes/n20darja/StageCesureCoeur/predict_tavi/ContrastiveLearning/Dataloader.py", line 25, in __getitem__
    hsm_cluster = pd.read_csv('clusters_hauteur.csv')
NameError: name 'pd' is not defined